<robot name="final_arm_urdf">

  <link name="base_link">
    <inertial>
      <origin xyz="-1.2317E-16 -2.498E-16 0.028906" rpy="0 0 0" />
      <mass value="0.59426" />
      <inertia ixx="0.0018342" ixy="-8.7929E-18" ixz="-2.6015E-19" iyy="0.0018342" iyz="1.9519E-19" izz="0.0036586" />
    </inertial>
    <visual>
      <origin xyz="0 0 0" rpy="0 0 0" />
      <geometry>
        <mesh filename="package://final_arm_urdf/meshes/visual/base_link.STL" />
      </geometry>
      <material name="">
        <color rgba="0.79216 0.81961 0.93333 1" />
      </material>
    </visual>
    <collision>
      <origin xyz="0 0 0" rpy="0 0 0" />
      <geometry>
        <mesh filename="package://final_arm_urdf/meshes/collision/base_link.STL" />
      </geometry>
    </collision>
  </link>
  <link name="link1">
    <inertial>
      <origin xyz="-0.0011483 1.4724E-06 0.061573" rpy="0 0 0" />
      <mass value="1.2427" />
      <inertia ixx="0.0017137" ixy="-2.8848E-09" ixz="4.6536E-05" iyy="0.00189" iyz="1.4625E-08" izz="0.0021854" />
    </inertial>
    <visual>
      <origin xyz="0 0 0" rpy="0 0 0" />
      <geometry>
        <mesh filename="package://final_arm_urdf/meshes/visual/link1.STL" />
      </geometry>
      <material name="">
        <color rgba="0.79216 0.81961 0.93333 1" />
      </material>
    </visual>
    <collision>
      <origin xyz="0 0 0" rpy="0 0 0" />
      <geometry>
        <mesh filename="package://final_arm_urdf/meshes/collision/link1.STL" />
      </geometry>
    </collision>
  </link>
  <joint name="joint1" type="revolute">
    <origin xyz="0 0 0" rpy="0 0 0" />
    <parent link="base_link" />
    <child link="link1" />
    <axis xyz="0 0 1" />
    <limit lower="0" upper="6.284" effort="300" velocity="3" />
    <calibration rising="0" falling="6.284" />
    <dynamics damping="0" friction="0" />
    <safety_controller soft_upper_limit="6.284" soft_lower_limit="0" k_position="0" k_velocity="0" />
  </joint>
  <link name="link2">
    <inertial>
      <origin xyz="7.0526E-07 0.092011 -0.029204" rpy="0 0 0" />
      <mass value="0.45196" />
      <inertia ixx="0.0004059" ixy="-7.0028E-09" ixz="-4.6156E-09" iyy="0.00031391" iyz="-3.6133E-06" izz="0.0003795" />
    </inertial>
    <visual>
      <origin xyz="0 0 0" rpy="0 0 0" />
      <geometry>
        <mesh filename="package://final_arm_urdf/meshes/visual/link2.STL" />
      </geometry>
      <material name="">
        <color rgba="0.79216 0.81961 0.93333 1" />
      </material>
    </visual>
    <collision>
      <origin xyz="0 0 0" rpy="0 0 0" />
      <geometry>
        <mesh filename="package://final_arm_urdf/meshes/collision/link2.STL" />
      </geometry>
    </collision>
  </link>
  <joint name="joint2" type="revolute">
    <origin xyz="0.0275 0 0.15538" rpy="1.5708 0 1.5708" />
    <parent link="link1" />
    <child link="link2" />
    <axis xyz="0 0 -1" />
    <limit lower="-1.571" upper="1.571" effort="300" velocity="3" />
    <calibration rising="0" falling="1.571" />
    <dynamics damping="0" friction="0" />
    <safety_controller soft_upper_limit="1.571" soft_lower_limit="-1.571" k_position="0" k_velocity="0" />
  </joint>
  <link name="link3">
    <inertial>
      <origin xyz="0.10219 -3.8224E-07 -0.025347" rpy="0 0 0" />
      <mass value="0.38558" />
      <inertia ixx="0.00026816" ixy="6.2277E-09" ixz="3.6385E-06" iyy="0.00032917" iyz="3.0322E-09" izz="0.00029965" />
    </inertial>
    <visual>
      <origin xyz="0 0 0" rpy="0 0 0" />
      <geometry>
        <mesh filename="package://final_arm_urdf/meshes/visual/link3.STL" />
      </geometry>
      <material name="">
        <color rgba="0.79216 0.81961 0.93333 1" />
      </material>
    </visual>
    <collision>
      <origin xyz="0 0 0" rpy="0 0 0" />
      <geometry>
        <mesh filename="package://final_arm_urdf/meshes/collision/link3.STL" />
      </geometry>
    </collision>
  </link>
  <joint name="joint3" type="revolute">
    <origin xyz="-0.00093484 0.17284 -0.0025" rpy="0 0 0" />
    <parent link="link2" />
    <child link="link3" />
    <axis xyz="0 0 1" />
    <limit lower="0" upper="3.142" effort="300" velocity="3" />
    <calibration rising="0" falling="3.142" />
    <dynamics damping="0" friction="0" />
    <safety_controller soft_upper_limit="3.142" soft_lower_limit="0" k_position="0" k_velocity="0" />
  </joint>
  <link name="link4">
    <inertial>
      <origin xyz="-2.4945E-06 0.090846 -0.024558" rpy="0 0 0" />
      <mass value="0.3087" />
      <inertia ixx="0.00021105" ixy="1.2263E-08" ixz="-2.3037E-08" iyy="0.0001769" iyz="-2.0811E-06" izz="0.00019916" />
    </inertial>
    <visual>
      <origin xyz="0 0 0" rpy="0 0 0" />
      <geometry>
        <mesh filename="package://final_arm_urdf/meshes/visual/link4.STL" />
      </geometry>
      <material name="">
        <color rgba="0.79216 0.81961 0.93333 1" />
      </material>
    </visual>
    <collision>
      <origin xyz="0 0 0" rpy="0 0 0" />
      <geometry>
        <mesh filename="package://final_arm_urdf/meshes/collision/link4.STL" />
      </geometry>
    </collision>
  </link>
  <joint name="joint4" type="revolute">
    <origin xyz="0.16934 0.00093484 0" rpy="0 0 0" />
    <parent link="link3" />
    <child link="link4" />
    <axis xyz="0 0 -1" />
    <limit lower="0" upper="3.142" effort="300" velocity="3" />
    <calibration rising="0" falling="3.142" />
    <dynamics damping="0" friction="0" />
    <safety_controller soft_upper_limit="3.142" soft_lower_limit="0" k_position="0" k_velocity="0" />
  </joint>
  <link name="link5">
    <inertial>
      <origin xyz="-0.0003626 0.020629 -0.033" rpy="0 0 0" />
      <mass value="0.11251" />
      <inertia ixx="8.0778E-05" ixy="9.3321E-07" ixz="3.4347E-21" iyy="2.7703E-05" iyz="-4.5715E-21" izz="7.2177E-05" />
    </inertial>
    <visual>
      <origin xyz="0 0 0" rpy="0 0 0" />
      <geometry>
        <mesh filename="package://final_arm_urdf/meshes/visual/link5.STL" />
      </geometry>
      <material name="">
        <color rgba="0.79216 0.81961 0.93333 1" />
      </material>
    </visual>
    <collision>
      <origin xyz="0 0 0" rpy="0 0 0" />
      <geometry>
        <mesh filename="package://final_arm_urdf/meshes/collision/link5.STL" />
      </geometry>
    </collision>
  </link>
  <joint name="joint5" type="revolute">
    <origin xyz="0 0.14633 0.0075" rpy="0 0 0" />
    <parent link="link4" />
    <child link="link5" />
    <axis xyz="0 0 1" />
    <limit lower="-1.571" upper="1.571" effort="300" velocity="3" />
    <calibration rising="0" falling="1.571" />
    <dynamics damping="0" friction="0" />
    <safety_controller soft_upper_limit="1.571" soft_lower_limit="-1.571" k_position="0" k_velocity="0" />
  </joint>
</robot>
